<?xml version="1.0"?>
<!-- Link Definitions -->
<robot name="ant_with_mesh">
<link name="base_link">
</link>

<!-- ************************************************************** -->
<!-- Ant Head Definition -->
<link name="head">
   <inertial>
     <origin xyz="0 0 0" rpy="0 0 0"/>
     <mass value="1"/>
     <inertia ixx="100"  ixy="0"  ixz="0" iyy="100" iyz="0" izz="100" />
   </inertial>
    <visual>
      <geometry>
      <mesh filename="package://simplified_messor_head.stl"/>
      </geometry>
    </visual>
    <collision>
      <origin rpy="0 0 0" xyz="0 0 0"/>   
      <geometry>
      <sphere radius="0.5"/>
      
      </geometry>
    </collision>
</link>

<link name="neck">
   <inertial>
     <origin xyz="0 0 0" rpy="0 0 0"/>
     <mass value="1"/>
     <inertia ixx="100"  ixy="0"  ixz="0" iyy="100" iyz="0" izz="100" />
   </inertial>
    <visual>
      <geometry>
        <sphere radius="0.2"/>
      </geometry>
    </visual>
    <collision>
      <geometry>
        <sphere radius="0.2"/>
      </geometry>
    </collision>
</link>

 <!-- <joint name="neck_joint_1" type="revolute"> -->
 <joint name="neck_joint_1" type="fixed">
     <origin xyz="0.0 0.0 0.0" rpy="0.0 0.0 0.0"/>
     <parent link="base_link"/>
     <child link="neck"/>
     <!-- <axis xyz="1.0 0.0 0.0"/>
     <limit lower="-1.0" upper="1.0" effort="0.5" velocity="0.5"/> -->
 </joint>


  <!-- Joint Definitions Neck-->
  <!-- <joint name="neck_joint_2" type="revolute"> -->
  <joint name="neck_joint_2" type="fixed">
     <origin xyz="0.0 0.69 0.2" rpy="0.0 0.0 0.0"/>
     <parent link="neck"/>
     <child link="head"/>
     <!-- <axis xyz="0.0 1.0 0.0"/>
     <limit lower="-1.0" upper="1.0" effort="0.0" velocity="0.0"/> -->
 </joint>
<!-- ************************************************************** -->
 <!-- Ant Mandible Definition -->
<!-- Link Definitions Mandible-->
<link name="mandible_base_link">
   <inertial>
     <origin xyz="0 0 0" rpy="0 0 0"/>
     <mass value="0.01"/>
     <inertia ixx="100"  ixy="0"  ixz="0" iyy="100" iyz="0" izz="100" />
   </inertial>
    <visual>
      <geometry>
        <sphere radius="0.2"/>
      </geometry>
    </visual>
    <collision>
      <geometry>
        <sphere radius="0.2"/>
      </geometry>
    </collision>
</link>

<!-- Left Jaw -->
<link name="left_jaw_base">
   <inertial>
     <origin xyz="0 0 0" rpy="0 0 0"/>
     <mass value="0.1"/>
     <inertia ixx="100"  ixy="0"  ixz="0" iyy="100" iyz="0" izz="100" />
   </inertial>
    <visual>
    <origin xyz="0.0 0.0 0.0" rpy="0.0 0.0 0.0"/>
      <geometry>
        <cylinder radius="0.15" length="0.4"/>
      </geometry>

    </visual>
    <collision>
    <origin xyz="0.0 0.0 0.0" rpy="0.0 0.0 0.0"/>
      <geometry>
        <cylinder radius="0.15" length="0.4"/>
      </geometry>
    </collision>
  </link>

<link name="left_jaw">
   <inertial>
     <origin xyz="0 0 0" rpy="0 0 0"/>
     <mass value="1"/>
     <inertia ixx="100"  ixy="0"  ixz="0" iyy="100" iyz="0" izz="100" />
   </inertial>
    <visual>
    <origin xyz="0.0 0.0 0.0" rpy="0.0 0.0 0.0"/>
      <geometry>
        <cylinder radius="0.15" length="0.5"/>
      </geometry>

    </visual>
    <collision>
    <origin xyz="0.0 0.0 0.0" rpy="0.0 0.0 0.0"/>
      <geometry>
        <cylinder radius="0.15" length="0.5"/>
      </geometry>
    </collision>
  </link>

  <link name="left_jaw_tip">
     <inertial>
     <origin xyz="0 0 0" rpy="0 0 0"/>
     <mass value="0.1"/>
     <inertia ixx="100"  ixy="0"  ixz="0" iyy="100" iyz="0" izz="100" />
   </inertial>
    <visual>
    <origin xyz="0.0 0.0 0.0" rpy="0.0 0.0 0.0"/>
      <geometry>
        <sphere radius="0.15"/>
      </geometry>

    </visual>
            <collision>
    <origin xyz="0.0 0.0 0.0" rpy="0.0 0.0 0.0"/>
      <geometry>
        <sphere radius="0.15"/>
      </geometry>
    </collision>
  </link>

<!-- Right Jaw -->
  <link name="right_jaw_base">
       <inertial>
     <origin xyz="0 0 0" rpy="0 0 0"/>
     <mass value="0.1"/>
     <inertia ixx="100"  ixy="0"  ixz="0" iyy="100" iyz="0" izz="100" />
   </inertial>
    <visual>
    <origin xyz="0.0 0.0 0.0" rpy="0.0 0.0 0.0"/>
      <geometry>
        <cylinder radius="0.15" length="0.4"/>
      </geometry>

    </visual>
        <collision>
    <origin xyz="0.0 0.0 0.0" rpy="0.0 0.0 0.0"/>
      <geometry>
        <cylinder radius="0.15" length="0."/>
      </geometry>
    </collision>
  </link>

  <link name="right_jaw">
       <inertial>
     <origin xyz="0 0 0" rpy="0 0 0"/>
     <mass value="1"/>
     <inertia ixx="100"  ixy="0"  ixz="0" iyy="100" iyz="0" izz="100" />
   </inertial>
    <visual>
    <origin xyz="0.0 0.0 0.0" rpy="0.0 0.0 0.0"/>
      <geometry>
        <cylinder radius="0.15" length="0.5"/>
      </geometry>
    </visual>
    <collision>
    <origin xyz="0.0 0.0 0.0" rpy="0.0 0.0 0.0"/>
      <geometry>
        <cylinder radius="0.15" length="0.5"/>
      </geometry>
    </collision>
  </link>

  <link name="right_jaw_tip">
       <inertial>
     <origin xyz="0 0 0" rpy="0 0 0"/>
     <mass value="0.1"/>
     <inertia ixx="100"  ixy="0"  ixz="0" iyy="100" iyz="0" izz="100" />
   </inertial>
    <visual>
    <origin xyz="0.0 0.0 0.0" rpy="0.0 0.0 0.0"/>
      <geometry>
        <sphere radius="0.15"/>
      </geometry>

    </visual>
        <collision>
    <origin xyz="0.0 0.0 0.0" rpy="0.0 0.0 0.0"/>
      <geometry>
        <sphere radius="0.15"/>
      </geometry>
    </collision>
  </link>

  <!-- Joint Definitions Mandible -->
 <joint name="left_attachment" type="revolute">
     <origin xyz="0.2 0.2 0.0" rpy="-0.95 1.7 0.0"/>
     <parent link="mandible_base_link"/>
     <child link="left_jaw_base"/>
     <axis xyz="-1.0 0.0 0.0"/>
     <limit lower="-0.1" upper="0.5" effort="1" velocity="1.0"/>

 </joint>
  <joint name="right_attachment" type="revolute">
     <origin xyz="0.2 -0.2 0.0" rpy="0.95 1.7 0.0"/>
     <parent link="mandible_base_link"/>
     <child link="right_jaw_base"/>
     <axis xyz="1.0 0.0 0.0"/>
     <limit lower="-0.1" upper="0.5" effort="1.0" velocity="1.0"/>

 </joint>


    <joint name="fixed_left_1" type="fixed">
     <origin xyz="0.0 -0.1 0.2" rpy="1.3 0.0 0.0"/>

        <parent link="left_jaw_base"/>
        <child link="left_jaw"/>
    </joint>
        <joint name="fixed_left_2" type="fixed">
        <origin xyz="0.0 0.0 0.3" rpy="1.3 0.0 0.0"/>

        <parent link="left_jaw"/>
        <child link="left_jaw_tip"/>
    </joint>

        <joint name="fixed_right_1" type="fixed">
     <origin xyz="0.0 0.1 0.2" rpy=" -1.3 0.0 0.0"/>

        <parent link="right_jaw_base"/>
        <child link="right_jaw"/>
    </joint>
        <joint name="fixed_right_2" type="fixed">
        <origin xyz="0.0 0.0 0.3" rpy="-1.3 0.0 0.0"/>

        <parent link="right_jaw"/>
        <child link="right_jaw_tip"/>
    </joint>

<!-- Attach mandible to head -->
 <joint name="head_mandible" type="fixed">
     <origin xyz="0.0 0.2 -0.2" rpy="0.0 0.3 1.57"/>
     <axis xyz="0.0 0.0 0.0"/>
     <parent link="head"/>
     <child link="mandible_base_link"/>
 </joint>

</robot>




